#VRML_SIM R2021a utf8
WorldInfo {
  basicTimeStep 2
  coordinateSystem "NUE"
  contactProperties [
    ContactProperties {
      coulombFriction [
        -1
      ]
    }
  ]
}
Viewpoint {
  orientation -0.0026149576340667364 -0.9953034897815503 -0.09676841026512446 3.083636629412373
  position 7.920433027062937 0.9501308090014775 -2.1742077749886666
  follow "Pioneer"
}
Floor {
  size 100 100
  appearance Parquetry {
    type "light strip"
  }
}
TexturedBackground {
}
TexturedBackgroundLight {
  castShadows FALSE
}
DEF Pioneer Robot {
  translation 8 0.587 0.75
  children [
    Accelerometer {
      translation -0.1 0.105 0
      children [
        Shape {
          appearance ShinyLeather {
            colorOverride 0 0 0.498039
          }
          geometry Cylinder {
            height 0.01
            radius 0.02
          }
        }
      ]
      name "Acc"
    }
    Gyro {
      translation 0 0.105 0
      children [
        Shape {
          appearance ShinyLeather {
            colorOverride 0 0.333333 0
          }
          geometry Cylinder {
            height 0.01
            radius 0.02
          }
        }
      ]
      name "Gyro"
    }
    InertialUnit {
      translation 0.1 0.105 0
      children [
        Shape {
          appearance ShinyLeather {
            colorOverride 0.666667 0 0
          }
          geometry Cylinder {
            height 0.01
            radius 0.02
          }
        }
      ]
      name "Imu"
    }
    DEF Body Solid {
      children [
        DEF BodyShape Shape {
          appearance CorrodedMetal {
          }
          geometry Box {
            size 0.3 0.2 0.3
          }
        }
        DEF LegLeft1 HingeJoint {
          jointParameters HingeJointParameters {
            position -0.75
            axis 0 0 1
            anchor 0 0 -0.165
          }
          device [
            PositionSensor {
              name "LegLeftPos1"
            }
            RotationalMotor {
              name "LegLeftMotor1"
              maxTorque 100
            }
          ]
          endPoint Solid {
            translation -0.10224581400350012 -0.10975333033107308 -0.165
            rotation 0 0 -1 0.75
            children [
              DEF LegLeftShape1 Shape {
                appearance Marble {
                }
                geometry Box {
                  size 0.076 0.3 0.03
                }
              }
              DEF LegLeft2 HingeJoint {
                jointParameters HingeJointParameters {
                  position 1.5
                  axis 0 0 1
                  anchor 0 -0.125 0
                }
                device [
                  PositionSensor {
                    name "LegLeftPos2"
                  }
                  RotationalMotor {
                    name "LegLeftMotor2"
                    maxTorque 100
                  }
                ]
                endPoint Solid {
                  translation 0.12468687332550676 -0.13384215020846288 0
                  rotation 0 0 1 1.5
                  children [
                    DEF WheelLeft HingeJoint {
                      jointParameters HingeJointParameters {
                        axis 0 0 1
                        anchor 0 -0.15 -0.01
                      }
                      device [
                        PositionSensor {
                          name "WheelLeftPos"
                        }
                        RotationalMotor {
                          name "WheelLeftMotor"
                          maxTorque 20
                        }
                      ]
                      endPoint Solid {
                        translation 0 -0.15 -0.035
                        rotation 1 0 0 1.5708
                        children [
                          DEF WheelLeftShape Shape {
                            appearance BakelitePlastic {
                            }
                            geometry Cylinder {
                              height 0.052
                              radius 0.185
                            }
                          }
                        ]
                        boundingObject USE WheelLeftShape
                        physics Physics {
                          density -1
                          mass 2
                        }
                      }
                    }
                    DEF LegLeftShape2 Shape {
                      appearance ShinyLeather {
                      }
                      geometry Box {
                        size 0.05 0.3 0.02
                      }
                    }
                  ]
                  name "solid(5)"
                  boundingObject USE LegLeftShape2
                  physics Physics {
                    density -1
                    mass 0.5
                  }
                }
              }
            ]
            name "solid(1)"
            boundingObject USE LegLeftShape1
            physics Physics {
              density -1
              mass 0.5
            }
          }
        }
        DEF LegRight1 HingeJoint {
          jointParameters HingeJointParameters {
            position -0.75
            axis 0 0 1
            anchor 0 0 0.165
          }
          device [
            PositionSensor {
              name "LegRightPos1"
            }
            RotationalMotor {
              name "LegRightMotor1"
              maxTorque 100
            }
          ]
          endPoint Solid {
            translation -0.10224581400350012 -0.10975333033107308 0.165
            rotation 0 0 -1 0.75
            children [
              DEF LegRightShape1 Shape {
                appearance Marble {
                }
                geometry Box {
                  size 0.076 0.3 0.03
                }
              }
              DEF LegRight2 HingeJoint {
                jointParameters HingeJointParameters {
                  position 1.5
                  axis 0 0 1
                  anchor 0 -0.125 0
                }
                device [
                  PositionSensor {
                    name "LegRightPos2"
                  }
                  RotationalMotor {
                    name "LegRightMotor2"
                    maxTorque 100
                  }
                ]
                endPoint Solid {
                  translation 0.12468687332550674 -0.13384215020846288 0
                  rotation 0 0 1 1.5
                  children [
                    DEF LegRightShape2 Shape {
                      appearance ShinyLeather {
                      }
                      geometry Box {
                        size 0.05 0.3 0.02
                      }
                    }
                    DEF WheelRight HingeJoint {
                      jointParameters HingeJointParameters {
                        axis 0 0 1
                        anchor 0 -0.15 0.01
                      }
                      device [
                        PositionSensor {
                          name "WheelRightPos"
                        }
                        RotationalMotor {
                          name "WheelRightMotor"
                          maxTorque 20
                        }
                      ]
                      endPoint Solid {
                        translation 0 -0.15 0.035
                        rotation 1 0 0 1.5707999999999998
                        children [
                          DEF WheelRightShape Shape {
                            appearance BakelitePlastic {
                            }
                            geometry Cylinder {
                              height 0.052
                              radius 0.185
                            }
                          }
                        ]
                        boundingObject USE WheelRightShape
                        physics Physics {
                          density -1
                          mass 2
                        }
                      }
                    }
                  ]
                  name "solid(4)"
                  boundingObject USE LegRightShape2
                  physics Physics {
                    density -1
                    mass 0.5
                  }
                }
              }
            ]
            name "solid(2)"
            boundingObject USE LegRightShape1
            physics Physics {
              density -1
              mass 0.5
            }
          }
        }
      ]
      boundingObject USE BodyShape
      physics Physics {
        density -1
        mass 6
      }
    }
  ]
  name "Pioneer"
  boundingObject USE BodyShape
  physics Physics {
    density -1
    mass 12
  }
  controller "Pioneer_Controller"
}
Solid {
  children [
    Solid {
      children [
        DEF pomian Shape {
          appearance PBRAppearance {
            roughness 1
            metalness 0
            name "DefaultMaterial"
          }
          geometry IndexedFaceSet {
            coord Coordinate {
              point [
                5.13397 0.5 1.5, 1.86603 0.5 1.5, 5.13395 0.499903 1.5, 0 0 1.5, 6.99961 0 1.5, 6.99961 0 0, 0 0 0, 5.13395 0.499903 0, 1.86603 0.5 0, 5.13397 0.5 0, 6.99961 0 1.5, 0 0 1.5, 6.99961 0 0, 0 0 0, 5.13397 0.5 1.5, 5.13397 0.5 0, 1.86603 0.5 1.5, 1.86603 0.5 0, 5.13397 0.5 1.5, 5.13395 0.499903 1.5, 5.13397 0.5 0, 5.13395 0.499903 0, 5.13395 0.499903 1.5, 6.99961 0 1.5, 5.13395 0.499903 0, 6.99961 0 0, 0 0 1.5, 1.86603 0.5 1.5, 0 0 0, 1.86603 0.5 0
              ]
            }
            normal Normal {
              vector [
                0 0 1, 0 0 1, 0 0 1, 0 0 1, 0 0 1, 0 0 -1, 0 0 -1, 0 0 -1, 0 0 -1, 0 0 -1, 0 -1 0, 0 -1 0, 0 -1 0, 0 -1 0, 0 1 0, 0 1 0, 0 1 0, 0 1 0, 0.965957 -0.258701 0, 0.965957 -0.258701 0, 0.965957 -0.258701 0, 0.965957 -0.258701 0, 0.258819 0.965926 0, 0.258819 0.965926 0, 0.258819 0.965926 0, 0.258819 0.965926 0, -0.258819 0.965926 0, -0.258819 0.965926 0, -0.258819 0.965926 0, -0.258819 0.965926 0
              ]
            }
            coordIndex [
              0, 1, 2, -1, 2, 1, 3, -1, 2, 3, 4, -1, 5, 6, 7, -1, 7, 6, 8, -1, 7, 8, 9, -1, 10, 11, 12, -1, 12, 11, 13, -1, 14, 15, 16, -1, 16, 15, 17, -1, 18, 19, 20, -1, 20, 19, 21, -1, 22, 23, 24, -1, 24, 23, 25, -1, 26, 27, 28, -1, 28, 27, 29, -1
            ]
          }
        }
      ]
      name ""
      boundingObject USE pomian
      physics Physics {
        density -1
        mass 50
      }
    }
  ]
  name "<STL_BINARY>"
}
Solid {
  translation 15 0.05 0
  children [
    DEF step Shape {
      geometry Box {
        size 3 0.1 3
      }
    }
  ]
  boundingObject USE step
  physics Physics {
    density -1
    mass 8
  }
}
